Workbook

Sheet Instructions
B1: Healthcare Interoperability Readiness Matrix for EMR Systems
B2: Tiered (Level 0–4) conformance testing of EMR systems applying to be used in the Health Information Exchange (HIE) for patient eReferral
B3: DRAFT — Version unreleased draft · branch main · commit a02e58b (built 2026-10-19 11:55 PHT). Thresholds and policy values are PROPOSED — for DOH approval. Definitions, the Technical Baseline (TB-), Terminology & Registry Sources (SRC-), FHIR Traceability (TR-), Indicator Definitions (IND-), Certification & Revalidation rules and the Glossary are in the companion document "HIE System Validation — Technical Reference Guide" (the Reference Guide).
B5: 1. WHAT THIS WORKBOOK DOES
B6: Decides, level by level, whether an EMR SYSTEM (the product) conforms to the national HL7 FHIR standards (PH Core and PHeReF) and may be used in the HIE for electronic referral. It tests the product on the DOH test environment (sandbox) with fictional test data only. Facility deployment (contracts, privacy registration, data sharing agreements, ICT assets, training) is outside this tool. Level 2D is security conformance testing — not a vulnerability assessment and penetration test (VAPT).
B8: 2. THE LEVELS (each level is a gate)
B9: • Level 0 Application & Commitment · Level 1 Product Documentation · Level 2 Interoperability Testing — 2A TS0 Terminology & Registries (test first), 2B TS1 Submission, 2C TS2 Retrieval, 2D Security, Reliability & Exception Handling (TEC- security checks and TS3- exception scenarios) · Level 3 Reports & Dashboard · Level 4 Advanced (Core-track and Maturity items).
B10: • Conformant for use in the HIE = Levels 0 to 3 PASSED and no critical item Not Met. Level 4 is the maturity target.
B12: 3. HOW TO SCORE A ROW
B13: • Binary: choose Met or Not Met. • Count / All-or-nothing: mark every ↳ sub-item Met / Not Met / Not Tested / N/A — the score is calculated. • Tier (L1-04 only): choose the integration level.
B14: • ★ / "Yes" in the Critical column = critical: it must be Met (N/A on a critical item counts as Not Met). • Not Tested blocks the level. • Always write the reason for N/A and the evidence reference in the Notes column.
B15: • Each row has a DEVELOPER'S GUIDE (what the vendor must prepare) and a VALIDATOR'S GUIDE (how to verify). Level 2 and 4 items must be confirmed with server-side evidence, not the EMR screen alone.
... B25: For anything not explained here — terms, ID prefixes, baselines, named sources, FHIR mappings, indicator rules, evidence options, roles of the Regional Validation Team and certification rules — see the HIE System Validation — Technical Reference Guide.

Sheet Summary
B1: Healthcare Interoperability Readiness Matrix for EMR Systems — Summary Scorecard
B2: System under test: | C2: ='System Profile'!C7&" "&'System Profile'!C8 | E2: Service provider: | F2: ='System Profile'!C6
B3: Applicant category: | C3: ='System Profile'!C14 | E3: Application no.: | F3: ='System Profile'!C5
B4: =IF($C$23="Approved","Threshold status: APPROVED by "&$C$24&" on "&TEXT($C$25,"dd mmm yyyy")&" ("&$C$26&")","Threshold status: PROPOSED — for DOH approval (see Threshold Policy below)")
B6: Level | C6: Score % | D6: Pass threshold | E6: Critical not met | F6: Items not tested | G6: Evaluation progress | H6: Sheet status | I6: LEVEL STATUS (gated)
B7: Level 0 — Application & Commitment | C7: ='L0 Application'!D4 | D7: 0.9 | E7: ='L0 Application'!D6 | F7: ='L0 Application'!F4 | G7: ='L0 Application'!D7 | H7: ='L0 Application'!F6 | I7: =H7
B8: Level 1 — Product Documentation | C8: ='L1 Documentation'!D4 | D8: 0.85 | E8: ='L1 Documentation'!D6 | F8: ='L1 Documentation'!F4 | G8: ='L1 Documentation'!D7 | H8: ='L1 Documentation'!F6 | I8: =IF(I7<>"PASSED","LOCKED",H8)
B9: Level 2 — Interoperability Testing (all parts) | C9: =IF((SUM('L2-A TS0-Terminology'!Q10:Q300)+SUM('L2-B TS1-Submission'!Q10:Q300)+SUM('L2-C TS2-Retrieval'!Q10:Q300)+SUM('L2-D System Resilience'!Q10:Q300))=0,0,(SUM('L2-A TS0-Terminology'!R10:R300)+SUM('L2-B TS1-Submission'!R10:R300)+SUM('L2-C TS2-Retrieval'!R10:R300)+SUM('L2-D System Resilience'!R10:R300))/(SUM('L2-A TS0-Terminology'!Q10:Q300)+SUM('L2-B TS1-Submission'!Q10:Q300)+SUM('L2-C TS2-Retrieval'!Q10:Q300)+SUM('L2-D System Resilience'!Q10:Q300))) | D9: All parts | E9: =SUM(E10:E13) | F9: =SUM(F10:F13) | G9: =IF(('L2-A TS0-Terminology'!F7+'L2-B TS1-Submission'!F7+'L2-C TS2-Retrieval'!F7+'L2-D System Resilience'!F7)=0,0,(('L2-A TS0-Terminology'!F7+'L2-B TS1-Submission'!F7+'L2-C TS2-Retrieval'!F7+'L2-D System Resilience'!F7)-F9)/('L2-A TS0-Terminology'!F7+'L2-B TS1-Submission'!F7+'L2-C TS2-Retrieval'!F7+'L2-D System Resilience'!F7)) | H9: =IF(F9>0,"INCOMPLETE",IF(AND(H10="PASSED",H11="PASSED",H12="PASSED",H13="PASSED"),"PASSED","NOT PASSED")) | I9: =IF(I8<>"PASSED","LOCKED",H9)
B10: 2A TS0 Terminology & Registries (gate) | C10: ='L2-A TS0-Terminology'!D4 | D10: 0.85 | E10: ='L2-A TS0-Terminology'!D6 | F10: ='L2-A TS0-Terminology'!F4 | G10: ='L2-A TS0-Terminology'!D7 | H10: ='L2-A TS0-Terminology'!F6 | I10: (part of Level 2)
B11: 2B TS1 eReferral Submission | C11: ='L2-B TS1-Submission'!D4 | D11: 0.85 | E11: ='L2-B TS1-Submission'!D6 | F11: ='L2-B TS1-Submission'!F4 | G11: ='L2-B TS1-Submission'!D7 | H11: ='L2-B TS1-Submission'!F6 | I11: (part of Level 2)
B12: 2C TS2 eReferral Retrieval | C12: ='L2-C TS2-Retrieval'!D4 | D12: 0.85 | E12: ='L2-C TS2-Retrieval'!D6 | F12: ='L2-C TS2-Retrieval'!F4 | G12: ='L2-C TS2-Retrieval'!D7 | H12: ='L2-C TS2-Retrieval'!F6 | I12: (part of Level 2)
B13: 2D Security, Reliability & Exception Handling | C13: ='L2-D System Resilience'!D4 | D13: 0.85 | E13: ='L2-D System Resilience'!D6 | F13: ='L2-D System Resilience'!F4 | G13: ='L2-D System Resilience'!D7 | H13: ='L2-D System Resilience'!F6 | I13: (part of Level 2)
B14: Level 3 — Reports & Dashboard | C14: ='L3 Reports'!D4 | D14: 0.85 | E14: ='L3 Reports'!D6 | F14: ='L3 Reports'!F4 | G14: ='L3 Reports'!D7 | H14: ='L3 Reports'!F6 | I14: =IF(I9<>"PASSED","LOCKED",H14)
B15: Level 4 — Advanced Interoperability | C15: ='L4 Advanced'!D4 | D15: 0.75 | E15: ='L4 Advanced'!D6 | F15: ='L4 Advanced'!F4 | G15: ='L4 Advanced'!D7 | H15: ='L4 Advanced'!F6 | I15: =IF(I14<>"PASSED","LOCKED",H15)
B18: HIGHEST LEVEL ACHIEVED | C18: =IF(I7<>"PASSED","None yet",IF(I8<>"PASSED","Level 0",IF(I9<>"PASSED","Level 1",IF(I14<>"PASSED","Level 2",IF(I15<>"PASSED","Level 3","Level 4")))))
B19: Conformant for use in the HIE? | C19: =IF(I14="PASSED","YES — Levels 0 to 3 passed; system may be offered to HIE facilities (Level 4 = advanced)"&IF($C$23<>"Approved"," — PROVISIONAL: pass thresholds not yet approved",""),"NOT YET")
B21: THRESHOLD POLICY (pass thresholds in column D above, and policy defaults in the Reference Guide, Ch. 3 and 7)
B22: Thresholds are DOH policy, not evaluator choices. Change the status to Approved only after approval is recorded; lock column D afterwards. All systems are evaluated against the same approved values.
B23: Policy status | C23: Proposed | F23: =IF(AND($C$23="Approved",OR($C$24="",$C$25="",$C$26="")),"⚠ Complete the approval details","")
B24: Approved by (body / meeting)
B25: Date approved
B26: Reference (resolution / minutes no.)
B28: COUNT REGISTER — live counts; quote these figures in presentations and review documents
B29: Sheet / part | C29: Criteria | D29: Critical criteria | E29: ★ critical sub-items | F29: Sub-items | G29: Info-only (W0) | H29: Scored criteria | I29: Pass threshold
B30: Level 0 | C30: =COUNTIF('L0 Application'!$T$10:$T$300,"Criterion") | D30: =COUNTIFS('L0 Application'!$H$10:$H$300,"Yes",'L0 Application'!$T$10:$T$300,"Criterion") | E30: =COUNTIFS('L0 Application'!$H$10:$H$300,"Yes",'L0 Application'!$T$10:$T$300,"Sub") | F30: =COUNTIF('L0 Application'!$T$10:$T$300,"Sub") | G30: =COUNTIFS('L0 Application'!$I$10:$I$300,0,'L0 Application'!$T$10:$T$300,"Criterion") | H30: =C30-G30 | I30: =D7
B31: Level 1 | C31: =COUNTIF('L1 Documentation'!$T$10:$T$300,"Criterion") | D31: =COUNTIFS('L1 Documentation'!$H$10:$H$300,"Yes",'L1 Documentation'!$T$10:$T$300,"Criterion") | E31: =COUNTIFS('L1 Documentation'!$H$10:$H$300,"Yes",'L1 Documentation'!$T$10:$T$300,"Sub") | F31: =COUNTIF('L1 Documentation'!$T$10:$T$300,"Sub") | G31: =COUNTIFS('L1 Documentation'!$I$10:$I$300,0,'L1 Documentation'!$T$10:$T$300,"Criterion") | H31: =C31-G31 | I31: =D8
B32: 2A TS0 | C32: =COUNTIF('L2-A TS0-Terminology'!$T$10:$T$300,"Criterion") | D32: =COUNTIFS('L2-A TS0-Terminology'!$H$10:$H$300,"Yes",'L2-A TS0-Terminology'!$T$10:$T$300,"Criterion") | E32: =COUNTIFS('L2-A TS0-Terminology'!$H$10:$H$300,"Yes",'L2-A TS0-Terminology'!$T$10:$T$300,"Sub") | F32: =COUNTIF('L2-A TS0-Terminology'!$T$10:$T$300,"Sub") | G32: =COUNTIFS('L2-A TS0-Terminology'!$I$10:$I$300,0,'L2-A TS0-Terminology'!$T$10:$T$300,"Criterion") | H32: =C32-G32 | I32: =D10
B33: 2B TS1 | C33: =COUNTIF('L2-B TS1-Submission'!$T$10:$T$300,"Criterion") | D33: =COUNTIFS('L2-B TS1-Submission'!$H$10:$H$300,"Yes",'L2-B TS1-Submission'!$T$10:$T$300,"Criterion") | E33: =COUNTIFS('L2-B TS1-Submission'!$H$10:$H$300,"Yes",'L2-B TS1-Submission'!$T$10:$T$300,"Sub") | F33: =COUNTIF('L2-B TS1-Submission'!$T$10:$T$300,"Sub") | G33: =COUNTIFS('L2-B TS1-Submission'!$I$10:$I$300,0,'L2-B TS1-Submission'!$T$10:$T$300,"Criterion") | H33: =C33-G33 | I33: =D11
B34: 2C TS2 | C34: =COUNTIF('L2-C TS2-Retrieval'!$T$10:$T$300,"Criterion") | D34: =COUNTIFS('L2-C TS2-Retrieval'!$H$10:$H$300,"Yes",'L2-C TS2-Retrieval'!$T$10:$T$300,"Criterion") | E34: =COUNTIFS('L2-C TS2-Retrieval'!$H$10:$H$300,"Yes",'L2-C TS2-Retrieval'!$T$10:$T$300,"Sub") | F34: =COUNTIF('L2-C TS2-Retrieval'!$T$10:$T$300,"Sub") | G34: =COUNTIFS('L2-C TS2-Retrieval'!$I$10:$I$300,0,'L2-C TS2-Retrieval'!$T$10:$T$300,"Criterion") | H34: =C34-G34 | I34: =D12
B35: 2D Security, Reliability & Exceptions | C35: =COUNTIF('L2-D System Resilience'!$T$10:$T$300,"Criterion") | D35: =COUNTIFS('L2-D System Resilience'!$H$10:$H$300,"Yes",'L2-D System Resilience'!$T$10:$T$300,"Criterion") | E35: =COUNTIFS('L2-D System Resilience'!$H$10:$H$300,"Yes",'L2-D System Resilience'!$T$10:$T$300,"Sub") | F35: =COUNTIF('L2-D System Resilience'!$T$10:$T$300,"Sub") | G35: =COUNTIFS('L2-D System Resilience'!$I$10:$I$300,0,'L2-D System Resilience'!$T$10:$T$300,"Criterion") | H35: =C35-G35 | I35: =D13
B36: Level 3 | C36: =COUNTIF('L3 Reports'!$T$10:$T$300,"Criterion") | D36: =COUNTIFS('L3 Reports'!$H$10:$H$300,"Yes",'L3 Reports'!$T$10:$T$300,"Criterion") | E36: =COUNTIFS('L3 Reports'!$H$10:$H$300,"Yes",'L3 Reports'!$T$10:$T$300,"Sub") | F36: =COUNTIF('L3 Reports'!$T$10:$T$300,"Sub") | G36: =COUNTIFS('L3 Reports'!$I$10:$I$300,0,'L3 Reports'!$T$10:$T$300,"Criterion") | H36: =C36-G36 | I36: =D14
B37: Level 4 | C37: =COUNTIF('L4 Advanced'!$T$10:$T$300,"Criterion") | D37: =COUNTIFS('L4 Advanced'!$H$10:$H$300,"Yes",'L4 Advanced'!$T$10:$T$300,"Criterion") | E37: =COUNTIFS('L4 Advanced'!$H$10:$H$300,"Yes",'L4 Advanced'!$T$10:$T$300,"Sub") | F37: =COUNTIF('L4 Advanced'!$T$10:$T$300,"Sub") | G37: =COUNTIFS('L4 Advanced'!$I$10:$I$300,0,'L4 Advanced'!$T$10:$T$300,"Criterion") | H37: =C37-G37 | I37: =D15
B38: TOTAL (all levels) | C38: =SUM(C30:C37) | D38: =SUM(D30:D37) | E38: =SUM(E30:E37) | F38: =SUM(F30:F37) | G38: =SUM(G30:G37) | H38: =SUM(H30:H37)
B39: of which Level 2 (all four parts) | C39: =SUM(C32:C35) | D39: =SUM(D32:D35) | E39: =SUM(E32:E35) | F39: =SUM(F32:F35) | G39: =SUM(G32:G35) | H39: =SUM(H32:H35)
B41: RETIRED / MOVED CRITERION IDs — IDs are never renumbered or reused
B42: ID | C42: Revision | D42: Action | E42: Now tested in | F42: Reason
B43: TEC-06 | C43: Rev 7 | D43: Moved | E43: TS3-05 | F43: Downtime handling now tested with retry / duplication checks in the TS3 exception scenarios of Level 2D.
B44: L4-06 | C44: Rev 7 | D44: Moved | E44: TS2-13 | F44: Status timestamps are fundamental — now critical in Level 2.
B45: L4-08 | C45: Rev 7 | D45: Moved | E45: TS1-16 | F45: Patient de-duplication is fundamental — now critical in Level 2.
B46: L4-09 | C46: Rev 7 | D46: Merged | E46: TS0-06.2 | F46: NHFR-sourced facility data checked with the NHFR critical sub-item.
...

Sheet System Profile
A1: System Profile
A2: Fill in the yellow cells. This information appears on the Summary sheet.
A4: A. GENERAL INFORMATION (to be accomplished by the Service Provider)
A5: A.0 | B5: Application No. (assigned by the Administrator)
A6: A.1 | B6: Name of Service Provider / Vendor
A7: A.2 | B7: System Name
A8: A.3 | B8: System Version / Build
A9: A.4 | B9: Developer / Technical Contact Name
A10: A.5 | B10: Designation
A11: A.6 | B11: Contact Number / Email
A12: A.7 | B12: Deployment type (Cloud / On-premise / Hybrid)
A13: B. APPLICANT CATEGORY
A14: B.1 | B14: Category (Third-party EMR provider / In-house developed system)
A15: B.2 | B15: Date application received by DOH
A16: B.3 | B16: Previous conformance result / reference no. (if re-evaluation)
A17: C. EVALUATION DETAILS — REGIONAL VALIDATION TEAM (these names appear on the Sign-Off of the Printed Evaluation Report)
B18: Role | C18: Name | D18: Name of Agency | E18: Designation
A19: C.1 | B19: Technical Lead (required)
A20: C.2 | B20: Validator 1 (required)
A21: C.3 | B21: Validator 2 (required)
A22: C.4 | B22: Validator 3 (optional)
A23: C.5 | B23: Administrator
A24: C.6 | B24: Observer 1 (required)
A25: C.7 | B25: Observer 2 (optional)
B26: Team composition check | C26: =IF(AND(C19<>"",COUNTA(C20:C22)>=2,COUNTA(C24:C25)>=1),"✓ Complete — "&COUNTA(C20:C22)&" validator(s), "&COUNTA(C24:C25)&" observer(s)","Incomplete — requires a Technical Lead, 2 to 3 validators and 1 to 2 observers")
A27: C.8 | B27: Date(s) of evaluation — Level 0
A28: C.9 | B28: Date(s) of evaluation — Level 1
A29: C.10 | B29: Date(s) of evaluation — Level 2
A30: C.11 | B30: Date(s) of evaluation — Level 3
A31: C.12 | B31: Date(s) of evaluation — Level 4
A32: C.13 | B32: Evaluation type (Initial / Re-evaluation after update)
A33: C.14 | B33: Conducting DOH office / region (printed on the report letterhead)
A35: D. VERSIONS TESTED AND CERTIFICATE (to be filled by the Regional Validation Team)
A36: D.1 | B36: Version / build actually tested (if different from A.3, record why) | D36: =IF(OR(C36="",C36=C8),"","⚠ Differs from A.3 — record the reason")
A37: D.2 | B37: PH Core IG version tested (e.g., 0.2.0)
A38: D.3 | B38: PHeReF IG version tested (e.g., 0.1.0)
A39: D.4 | B39: Terminology / PSGC release used on the sandbox
A40: D.5 | B40: Certificate no. (assigned on approval)
A41: D.6 | B41: Date of approval
A42: D.7 | B42: Valid until (auto: 2 years from approval — PROPOSED) | C42: =IF(C41="","",EDATE(C41,24))
...

Sheet Test Data
A1: Test Data — standard values for Level 2 and Level 3 testing
A2: ALL DATA ARE FICTIONAL and for testing only — not clinical advice. Replace the [bracketed] placeholders with the official test facilities/IDs issued by the DOH before testing. The same values must be used for every system evaluated. ★ = critical sub-item.
A4: SECTION A — Test referral (enter in the referring EMR for TS1; compare on the receiving EMR for TS2)
A5: Ref (criterion / sub-item) | B5: Data element | C5: Test value to enter | D5: Value seen at receiving EMR (TS2)
A6: TS1-01.1 | B6: HCPN name | C6: [Test Dummy HCPN name]
A7: TS1-01.2 | B7: Initiating (referring) facility name | C7: [Test referring facility]
A8: TS1-01.3 | B8: Initiating facility NHFR code ★ | C8: [NHFR code of test referring facility]
A9: TS1-01.4 | B9: Initiating facility address | C9: [Official address, PSGC-coded]
A10: TS1-01.5 | B10: Initiating facility contact number | C10: [Facility landline/mobile]
A11: TS1-02.1 | B11: Receiving facility name | C11: [Test receiving facility]
A12: TS1-02.2 | B12: Receiving facility NHFR code ★ | C12: [NHFR code of test receiving facility]
A13: TS1-02.3 | B13: Receiving facility address | C13: [Official address, PSGC-coded]
A14: TS1-03.1 | B14: Name of referring practitioner | C14: TEST Dr. Ana Reyes
A15: TS1-03.2 | B15: Referring practitioner role ★ | C15: Medical practitioner (SNOMED CT 158965000)
A16: TS1-03.3 | B16: Care navigator at referring facility (if assigned) | C16: TEST Nurse Liza Cruz
A17: TS1-04.1 | B17: Patient full name | C17: TEST Maria Santos
... A51: TS2-11 | B51: Receiving response sequence ★ | C51: received → accepted → completed; second referral: rejected (reason: no available bed)
A53: SECTION B — Level 3 reconciliation set: 10 mock test referrals with KNOWN outcomes. Perspective = the facility under test ("Facility A").
A54: Create all 10 referrals in the system during testing. Enter the actual date/time referred and received as they happen (yellow). The Expected Results below calculate automatically; the system's reports must match them exactly. Column M (working impression) is used for the Top Morbidity check (L3-16).
A55: # | B55: Referring facility | C55: Receiving facility | D55: Direction (for Facility A) | E55: Referring facility ownership | F55: Receiving facility capability | G55: Category | H55: Reason for referral | I55: Final status | J55: Date/time referred | K55: Date/time received | L55: TAT (minutes) | M55: Working impression (morbidity, ICD-10)
A56: 1 | B56: Facility A | C56: Facility B | D56: Outgoing | E56: Government | F56: Level 1 | G56: Emergency | H56: Consultation | I56: Received | L56: =IF(AND(ISNUMBER(J56),ISNUMBER(K56)),(K56-J56)*1440,"") | M56: J18.9 — Pneumonia, unspecified organism
A57: 2 | B57: Facility A | C57: Facility B | D57: Outgoing | E57: Government | F57: Level 1 | G57: Outpatient | H57: Diagnostics | I57: Redirected | L57: =IF(AND(ISNUMBER(J57),ISNUMBER(K57)),(K57-J57)*1440,"") | M57: O14.1 — Severe pre-eclampsia
A58: 3 | B58: Facility A | C58: Facility C | D58: Outgoing | E58: Government | F58: Level 2 | G58: Outpatient | H58: Consultation | I58: Deferred/Denied | L58: =IF(AND(ISNUMBER(J58),ISNUMBER(K58)),(K58-J58)*1440,"") | M58: J18.9 — Pneumonia, unspecified organism
A59: 4 | B59: Facility A | C59: Facility C | D59: Outgoing | E59: Government | F59: Level 2 | G59: Emergency | H59: Procedure | I59: Received | L59: =IF(AND(ISNUMBER(J59),ISNUMBER(K59)),(K59-J59)*1440,"") | M59: I10 — Essential (primary) hypertension
A60: 5 | B60: Facility A | C60: Facility D | D60: Outgoing | E60: Government | F60: Level 3 | G60: Emergency | H60: Consultation | I60: Redirected | L60: =IF(AND(ISNUMBER(J60),ISNUMBER(K60)),(K60-J60)*1440,"") | M60: O14.1 — Severe pre-eclampsia
A61: 6 | B61: Facility A | C61: Facility B | D61: Outgoing | E61: Government | F61: Level 1 | G61: Outpatient | H61: Consultation | I61: Received | L61: =IF(AND(ISNUMBER(J61),ISNUMBER(K61)),(K61-J61)*1440,"") | M61: J18.9 — Pneumonia, unspecified organism
A62: 7 | B62: Facility E | C62: Facility A | D62: Incoming | E62: Government | F62: RHU | G62: Outpatient | H62: Diagnostics | I62: Received | L62: =IF(AND(ISNUMBER(J62),ISNUMBER(K62)),(K62-J62)*1440,"") | M62: A09 — Infectious gastroenteritis and colitis
A63: 8 | B63: Facility F | C63: Facility A | D63: Incoming | E63: Private | F63: RHU | G63: Emergency | H63: Consultation | I63: Received | L63: =IF(AND(ISNUMBER(J63),ISNUMBER(K63)),(K63-J63)*1440,"") | M63: O14.1 — Severe pre-eclampsia
A64: 9 | B64: Facility F | C64: Facility A | D64: Incoming | E64: Private | F64: RHU | G64: Outpatient | H64: Others | I64: Deferred/Denied | L64: =IF(AND(ISNUMBER(J64),ISNUMBER(K64)),(K64-J64)*1440,"") | M64: I10 — Essential (primary) hypertension
A65: 10 | B65: Facility E | C65: Facility A | D65: Incoming | E65: Government | F65: RHU | G65: Emergency | H65: Diagnostics | I65: Received | L65: =IF(AND(ISNUMBER(J65),ISNUMBER(K65)),(K65-J65)*1440,"") | M65: J18.9 — Pneumonia, unspecified organism
A67: EXPECTED RESULTS (auto-calculated — compare with the system's reports in Level 3)
A68: Expected result | B68: Expected value | C68: Value in system report | D68: Match?
A69: Total referrals in linelist | B69: =COUNTA($A$56:$A$65) | D69: =IF(C69="","",IF(ISNUMBER(B69),IF(ABS(C69-B69)<=IF(A69="Average turnaround time (minutes)",1,0),"MATCH","MISMATCH"),""))
A70: Outgoing referrals | B70: =COUNTIF($D$56:$D$65,"Outgoing") | D70: =IF(C70="","",IF(ISNUMBER(B70),IF(ABS(C70-B70)<=IF(A70="Average turnaround time (minutes)",1,0),"MATCH","MISMATCH"),""))
A71: Incoming referrals | B71: =COUNTIF($D$56:$D$65,"Incoming") | D71: =IF(C71="","",IF(ISNUMBER(B71),IF(ABS(C71-B71)<=IF(A71="Average turnaround time (minutes)",1,0),"MATCH","MISMATCH"),""))
A72: Received (incoming AND status Received) | B72: =COUNTIFS($D$56:$D$65,"Incoming",$I$56:$I$65,"Received") | D72: =IF(C72="","",IF(ISNUMBER(B72),IF(ABS(C72-B72)<=IF(A72="Average turnaround time (minutes)",1,0),"MATCH","MISMATCH"),""))
A73: Deferred / denied (all) | B73: =COUNTIF($I$56:$I$65,"Deferred/Denied") | D73: =IF(C73="","",IF(ISNUMBER(B73),IF(ABS(C73-B73)<=IF(A73="Average turnaround time (minutes)",1,0),"MATCH","MISMATCH"),""))
A74: Redirected (all) | B74: =COUNTIF($I$56:$I$65,"Redirected") | D74: =IF(C74="","",IF(ISNUMBER(B74),IF(ABS(C74-B74)<=IF(A74="Average turnaround time (minutes)",1,0),"MATCH","MISMATCH"),""))
A75: Reason: Consultation | B75: =COUNTIF($H$56:$H$65,"Consultation") | D75: =IF(C75="","",IF(ISNUMBER(B75),IF(ABS(C75-B75)<=IF(A75="Average turnaround time (minutes)",1,0),"MATCH","MISMATCH"),""))
A76: Reason: Diagnostics | B76: =COUNTIF($H$56:$H$65,"Diagnostics") | D76: =IF(C76="","",IF(ISNUMBER(B76),IF(ABS(C76-B76)<=IF(A76="Average turnaround time (minutes)",1,0),"MATCH","MISMATCH"),""))
...

Sheet L0 Application
A1: Level 0 — Application & Commitment
A2: The vendor/developer formally applies and commits to the process. All items are documents. Critical items (red) must all be Met.
C4: Level / section score | D4: =IF(SUM(Q10:Q300)=0,0,SUM(R10:R300)/SUM(Q10:Q300)) | E4: Items not yet tested | F4: =COUNTIFS(M10:M300,"Not Tested",T10:T300,"Criterion") | G4: Count criteria: mark each sub-item (rows marked ↳). Required, Achieved, Result and Outstanding are calculated automatically.
C5: Pass threshold (set on Summary) | D5: =Summary!D7 | E5: Items marked N/A | F5: =COUNTIFS(M10:M300,"N/A",T10:T300,"Criterion")
C6: Critical criteria not met (tested items) | D6: =SUM(S10:S300) | E6: Sheet status | F6: =IF(F4>0,"INCOMPLETE",IF(AND(D6=0,D4>=D5),"PASSED","NOT PASSED"))
C7: Evaluation progress (items evaluated) | D7: =IF(F7=0,0,(F7-F4)/F7) | E7: Total items | F7: =COUNTIF(T10:T300,"Criterion")
A9: Ref ID | B9: Section | C9: Criterion (what is checked) | D9: Developer's Guide (what the vendor must prepare / implement) | E9: Validator's Guide (how the Validators verify) | F9: Evidence required | G9: Validation role | H9: Critical? | I9: Weight | J9: Scoring type | K9: Required (n) | L9: Achieved (n) | M9: Result | N9: Score % | O9: Outstanding (auto) | P9: Evidence ref. / Notes | Q9: Applicable wt | R9: Earned wt | S9: Critical fail | T9: Row type | U9: Sub not met | V9: Sub tested | W9: Needs compliance (ID)
A10: L0-01 | B10: Application | C10: Letter of application to have the EMR system tested for use in the HIE, signed by the vendor's/developer's authorized signatory | D10: Submit a letter of application on official letterhead, signed by an authorized signatory, with proof of authority (secretary's certificate / board resolution; office order for in-house systems). Purpose: The vendor or developer formally asks to be evaluated. | E10: Check the letter is on official letterhead, dated, and signed by an authorized signatory (with proof of authority, e.g. secretary's certificate or office order for in-house systems). | F10: Signed letter of application + proof of authority | G10: Validator | H10: Yes | I10: 2 | J10: Binary | M10: Not Tested | N10: =IF(M10="N/A",IF(H10="Yes",0,""),IF(M10="Not Tested",0,IF(J10="Tier",IF(M10="Fully integrated",1,IF(M10="Standalone - manual encoding",0.5,0)),IF(J10="Binary",IF(M10="Met",1,0),IF(M10="Counted",IF(N(K10)>0,IF(J10="All-or-nothing",IF(N(L10)>=K10,1,0),MIN(N(L10)/K10,1)),0),0))))) | O10: =IF(M10="Not Met","Needs compliance",IF(M10="Not Tested","Not yet tested","")) | Q10: =IF(N10="",0,I10) | R10: =IF(N10="",0,I10*N10) | S10: =IF(AND(H10="Yes",M10<>"Not Tested",N10<>"",N10<1),1,0) | T10: Criterion | W10: =IF(AND(T10="Criterion",I10>0,M10<>"Not Tested",N10<>"",OR(N(N10)<1,S10=1)),A10,"")
A11: L0-02 | B11: Contacts | C11: Vendor/developer contact persons designated: (1) product/technical lead, (2) integration (FHIR) developer, (3) data privacy contact | D11: Name three contact persons — product/technical lead, FHIR integration developer, data privacy contact — with position, email and mobile number. Purpose: The DOH knows who is accountable for the product, the integration and privacy questions during testing. | E11: Count the roles with a named person, position and contact details in the letter or designation. Mark each sub-item (↳) below; Achieved is counted automatically. | F11: Designation / contact list | G11: Validator | H11: Yes | I11: 2 | J11: Count | K11: =COUNTA(A12:A14)-COUNTIF(M12:M14,"N/A") | L11: =COUNTIF(M12:M14,"Met") | M11: =IF(COUNTIF(M12:M14,"N/A")=COUNTA(A12:A14),"N/A",IF(COUNTIF(M12:M14,"Not Tested")>0,"Not Tested","Counted")) | N11: =IF(M11="N/A",IF(H11="Yes",0,""),IF(M11="Not Tested",0,IF(J11="Tier",IF(M11="Fully integrated",1,IF(M11="Standalone - manual encoding",0.5,0)),IF(J11="Binary",IF(M11="Met",1,0),IF(M11="Counted",IF(N(K11)>0,IF(J11="All-or-nothing",IF(N(L11)>=K11,1,0),MIN(N(L11)/K11,1)),0),0))))) | O11: =IF(COUNTIF(M12:M14,"Not Met")>0,COUNTIF(M12:M14,"Not Met")&" of "&K11&" need compliance: "&_xlfn.TEXTJOIN("; ",TRUE(),U12:U14),IF(COUNTIF(M12:M14,"Not Tested")>0,COUNTIF(M12:M14,"Not Tested")&" of "&COUNTA(A12:A14)&" not yet tested",IF(M11="N/A","","All compliant"))) | Q11: =IF(N11="",0,I11) | R11: =IF(N11="",0,I11*N11) | S11: =IF(OR(AND(H11="Yes",M11<>"Not Tested",N11<>"",N11<1),COUNTIFS(H12:H14,"Yes",M12:M14,"Not Met")+COUNTIFS(H12:H14,"Yes",M12:M14,"N/A")>0),1,0) | T11: Criterion | V11: =COUNTA(A12:A14)-COUNTIF(M12:M14,"Not Tested") | W11: =IF(AND(T11="Criterion",I11>0,M11<>"Not Tested",N11<>"",OR(N(N11)<1,S11=1)),A11,"")
A12: L0-02.1 | B12: ↳ sub-item | C12: Product / technical lead named (position, email, mobile) | D12: (part of L0-02) | M12: Not Tested | O12: =IF(M12="Not Met","Needs compliance",IF(M12="Not Tested","Not yet tested","")) | T12: Sub | U12: =IF(M12="Not Met","("&1&") "&IF(H12="Yes","★ ","")&C12,"")
A13: L0-02.2 | B13: ↳ sub-item | C13: Integration (FHIR) developer named (position, email, mobile) | D13: (part of L0-02) | M13: Not Tested | O13: =IF(M13="Not Met","Needs compliance",IF(M13="Not Tested","Not yet tested","")) | T13: Sub | U13: =IF(M13="Not Met","("&2&") "&IF(H13="Yes","★ ","")&C13,"")
A14: L0-02.3 | B14: ↳ sub-item | C14: Data privacy contact named (position, email, mobile) | D14: (part of L0-02) | M14: Not Tested | O14: =IF(M14="Not Met","Needs compliance",IF(M14="Not Tested","Not yet tested","")) | T14: Sub | U14: =IF(M14="Not Met","("&3&") "&IF(H14="Yes","★ ","")&C14,"")
A15: L0-03 | B15: System | C15: EMR system identified: product name, version/build under test, deployment model, facility types it is offered for | D15: Complete the System Profile Sheet: product name, exact version/build to be tested, deployment model, and facility types the system is offered for. Purpose: We know exactly which system and version is being tested; results apply to that version only. | E15: Check System Profile A.1–A.7 and B.1–B.2 are complete and match the letter. | F15: Completed System Profile | G15: Validator | H15: Yes | I15: 2 | J15: Binary | M15: Not Tested | N15: =IF(M15="N/A",IF(H15="Yes",0,""),IF(M15="Not Tested",0,IF(J15="Tier",IF(M15="Fully integrated",1,IF(M15="Standalone - manual encoding",0.5,0)),IF(J15="Binary",IF(M15="Met",1,0),IF(M15="Counted",IF(N(K15)>0,IF(J15="All-or-nothing",IF(N(L15)>=K15,1,0),MIN(N(L15)/K15,1)),0),0))))) | O15: =IF(M15="Not Met","Needs compliance",IF(M15="Not Tested","Not yet tested","")) | Q15: =IF(N15="",0,I15) | R15: =IF(N15="",0,I15*N15) | S15: =IF(AND(H15="Yes",M15<>"Not Tested",N15<>"",N15<1),1,0) | T15: Criterion | W15: =IF(AND(T15="Criterion",I15>0,M15<>"Not Tested",N15<>"",OR(N(N15)<1,S15=1)),A15,"")
A16: L0-04 | B16: Commitment | C16: Signed undertaking to conform to the PH Core and PHeReF IGs, to be re-tested on IG version change or major system release, and to use only test data on the sandbox | D16: Sign the undertaking to (1) conform to PH Core and PHeReF, (2) request re-testing on IG version change or major release, and (3) use only test data on the sandbox. Purpose: Because the IGs are drafts, the vendor agrees to keep up with updates; no real patient data is used in testing. | E16: Check the signed undertaking names both IGs, the re-test clause and the test-data-only clause. | F16: Signed undertaking | G16: Validator | H16: Yes | I16: 2 | J16: Binary | M16: Not Tested | N16: =IF(M16="N/A",IF(H16="Yes",0,""),IF(M16="Not Tested",0,IF(J16="Tier",IF(M16="Fully integrated",1,IF(M16="Standalone - manual encoding",0.5,0)),IF(J16="Binary",IF(M16="Met",1,0),IF(M16="Counted",IF(N(K16)>0,IF(J16="All-or-nothing",IF(N(L16)>=K16,1,0),MIN(N(L16)/K16,1)),0),0))))) | O16: =IF(M16="Not Met","Needs compliance",IF(M16="Not Tested","Not yet tested","")) | Q16: =IF(N16="",0,I16) | R16: =IF(N16="",0,I16*N16) | S16: =IF(AND(H16="Yes",M16<>"Not Tested",N16<>"",N16<1),1,0) | T16: Criterion | W16: =IF(AND(T16="Criterion",I16>0,M16<>"Not Tested",N16<>"",OR(N(N16)<1,S16=1)),A16,"")
A17: L0-05 | B17: Coordination | C17: Contact persons (from L0-02) attended the initial coordination meeting with the Regional Validation Team (in person or virtual) | D17: Ensure the three contact persons attend the initial coordination meeting with the Regional Validation Team (in person or virtual) to agree on the process and schedule. Purpose: The vendor understands the process and the schedule before testing begins. | E17: Count the contact persons in the attendance / minutes of the coordination meeting. Mark each sub-item (↳) below; Achieved is counted automatically. | F17: Attendance sheet or minutes of the coordination meeting | G17: Validator | H17: No | I17: 1 | J17: Count | K17: =COUNTA(A18:A20)-COUNTIF(M18:M20,"N/A") | L17: =COUNTIF(M18:M20,"Met") | M17: =IF(COUNTIF(M18:M20,"N/A")=COUNTA(A18:A20),"N/A",IF(COUNTIF(M18:M20,"Not Tested")>0,"Not Tested","Counted")) | N17: =IF(M17="N/A",IF(H17="Yes",0,""),IF(M17="Not Tested",0,IF(J17="Tier",IF(M17="Fully integrated",1,IF(M17="Standalone - manual encoding",0.5,0)),IF(J17="Binary",IF(M17="Met",1,0),IF(M17="Counted",IF(N(K17)>0,IF(J17="All-or-nothing",IF(N(L17)>=K17,1,0),MIN(N(L17)/K17,1)),0),0))))) | O17: =IF(COUNTIF(M18:M20,"Not Met")>0,COUNTIF(M18:M20,"Not Met")&" of "&K17&" need compliance: "&_xlfn.TEXTJOIN("; ",TRUE(),U18:U20),IF(COUNTIF(M18:M20,"Not Tested")>0,COUNTIF(M18:M20,"Not Tested")&" of "&COUNTA(A18:A20)&" not yet tested",IF(M17="N/A","","All compliant"))) | Q17: =IF(N17="",0,I17) | R17: =IF(N17="",0,I17*N17) | S17: =IF(OR(AND(H17="Yes",M17<>"Not Tested",N17<>"",N17<1),COUNTIFS(H18:H20,"Yes",M18:M20,"Not Met")+COUNTIFS(H18:H20,"Yes",M18:M20,"N/A")>0),1,0) | T17: Criterion | V17: =COUNTA(A18:A20)-COUNTIF(M18:M20,"Not Tested") | W17: =IF(AND(T17="Criterion",I17>0,M17<>"Not Tested",N17<>"",OR(N(N17)<1,S17=1)),A17,"")
A18: L0-05.1 | B18: ↳ sub-item | C18: Product / technical lead attended the coordination meeting | D18: (part of L0-05) | M18: Not Tested | O18: =IF(M18="Not Met","Needs compliance",IF(M18="Not Tested","Not yet tested","")) | T18: Sub | U18: =IF(M18="Not Met","("&1&") "&IF(H18="Yes","★ ","")&C18,"")
A19: L0-05.2 | B19: ↳ sub-item | C19: Integration (FHIR) developer attended the coordination meeting | D19: (part of L0-05) | M19: Not Tested | O19: =IF(M19="Not Met","Needs compliance",IF(M19="Not Tested","Not yet tested","")) | T19: Sub | U19: =IF(M19="Not Met","("&2&") "&IF(H19="Yes","★ ","")&C19,"")
A20: L0-05.3 | B20: ↳ sub-item | C20: Data privacy contact attended the coordination meeting | D20: (part of L0-05) | M20: Not Tested | O20: =IF(M20="Not Met","Needs compliance",IF(M20="Not Tested","Not yet tested","")) | T20: Sub | U20: =IF(M20="Not Met","("&3&") "&IF(H20="Yes","★ ","")&C20,"")
A21: L0-06 | B21: Access | C21: Access to the test (sandbox) endpoint requested and granted | D21: Request sandbox (test endpoint) access from the Regional Validation Team and confirm a successful connection. Purpose: The vendor can connect to the test servers. | E21: Check the confirmation email / access log from the endpoint administrator. | F21: Access confirmation | G21: Validator | H21: No | I21: 1 | J21: Binary | M21: Not Tested | N21: =IF(M21="N/A",IF(H21="Yes",0,""),IF(M21="Not Tested",0,IF(J21="Tier",IF(M21="Fully integrated",1,IF(M21="Standalone - manual encoding",0.5,0)),IF(J21="Binary",IF(M21="Met",1,0),IF(M21="Counted",IF(N(K21)>0,IF(J21="All-or-nothing",IF(N(L21)>=K21,1,0),MIN(N(L21)/K21,1)),0),0))))) | O21: =IF(M21="Not Met","Needs compliance",IF(M21="Not Tested","Not yet tested","")) | Q21: =IF(N21="",0,I21) | R21: =IF(N21="",0,I21*N21) | S21: =IF(AND(H21="Yes",M21<>"Not Tested",N21<>"",N21<1),1,0) | T21: Criterion | W21: =IF(AND(T21="Criterion",I21>0,M21<>"Not Tested",N21<>"",OR(N(N21)<1,S21=1)),A21,"")

Sheet L1 Documentation
A1: Level 1 — Product Documentation
A2: Documentation of the EMR system itself. Facility-level legal, privacy, infrastructure and personnel requirements are outside the scope of this tool.
C4: Level / section score | D4: =IF(SUM(Q10:Q300)=0,0,SUM(R10:R300)/SUM(Q10:Q300)) | E4: Items not yet tested | F4: =COUNTIFS(M10:M300,"Not Tested",T10:T300,"Criterion") | G4: Count criteria: mark each sub-item (rows marked ↳). Required, Achieved, Result and Outstanding are calculated automatically.
C5: Pass threshold (set on Summary) | D5: =Summary!D8 | E5: Items marked N/A | F5: =COUNTIFS(M10:M300,"N/A",T10:T300,"Criterion")
C6: Critical criteria not met (tested items) | D6: =SUM(S10:S300) | E6: Sheet status | F6: =IF(F4>0,"INCOMPLETE",IF(AND(D6=0,D4>=D5),"PASSED","NOT PASSED"))
C7: Evaluation progress (items evaluated) | D7: =IF(F7=0,0,(F7-F4)/F7) | E7: Total items | F7: =COUNTIF(T10:T300,"Criterion")
A9: Ref ID | B9: Section | C9: Criterion (what is checked) | D9: Developer's Guide (what the vendor must prepare / implement) | E9: Validator's Guide (how the Validators verify) | F9: Evidence required | G9: Validation role | H9: Critical? | I9: Weight | J9: Scoring type | K9: Required (n) | L9: Achieved (n) | M9: Result | N9: Score % | O9: Outstanding (auto) | P9: Evidence ref. / Notes | Q9: Applicable wt | R9: Earned wt | S9: Critical fail | T9: Row type | U9: Sub not met | V9: Sub tested | W9: Needs compliance (ID)
A10: L1-01 | B10: Workflow | C10: Process flows of the eReferral module as implemented in the system, for ALL three: (a) referring, (b) receiving, (c) back-referral | D10: Submit process flow diagrams of the eReferral module for referring, receiving and back-referral, showing the actual system screens and steps. Purpose: Shows how the system moves a referral step by step. All three are required (all-or-nothing, per DOH draft). | E10: Check that diagrams exist for all three flows and show the system screens/steps. If any one is missing, mark Not Met. | F10: Process flow diagrams | G10: Validator | H10: No | I10: 3 | J10: Binary | M10: Not Tested | N10: =IF(M10="N/A",IF(H10="Yes",0,""),IF(M10="Not Tested",0,IF(J10="Tier",IF(M10="Fully integrated",1,IF(M10="Standalone - manual encoding",0.5,0)),IF(J10="Binary",IF(M10="Met",1,0),IF(M10="Counted",IF(N(K10)>0,IF(J10="All-or-nothing",IF(N(L10)>=K10,1,0),MIN(N(L10)/K10,1)),0),0))))) | O10: =IF(M10="Not Met","Needs compliance",IF(M10="Not Tested","Not yet tested","")) | Q10: =IF(N10="",0,I10) | R10: =IF(N10="",0,I10*N10) | S10: =IF(AND(H10="Yes",M10<>"Not Tested",N10<>"",N10<1),1,0) | T10: Criterion | W10: =IF(AND(T10="Criterion",I10>0,M10<>"Not Tested",N10<>"",OR(N(N10)<1,S10=1)),A10,"")
A11: L1-02 | B11: Manual | C11: User manual of the eReferral module contains ALL seven required sections (all-or-nothing): (1) system overview & user roles, (2) referring workflow step-by-step, (3) receiving workflow step-by-step, (4) back-referral workflow, (5) downtime/offline behaviour, (6) troubleshooting & error messages, (7) vendor support contacts & escalation | D11: Submit the eReferral module user manual with a table of contents covering ALL 7 required sections, including how users check the server status and what the system does during downtime or offline operation. Titles, order and format (printed, PDF or online help) are the vendor's choice — only the content is checked. Purpose: Checks the CONTENT of the manual once, at product level. All seven sections are required: a manual missing any one section scores 0% (all-or-nothing). | E11: Check the table of contents and the body of the manual for each of the 7 sections. Mark each sub-item (↳) below so missing sections are listed. All-or-nothing: the criterion scores 100% only if ALL 7 sub-items are Met; if any one is Not Met the score is 0%. | F11: User manual | G11: Validator | H11: No | I11: 2 | J11: All-or-nothing | K11: =COUNTA(A12:A18)-COUNTIF(M12:M18,"N/A") | L11: =COUNTIF(M12:M18,"Met") | M11: =IF(COUNTIF(M12:M18,"N/A")=COUNTA(A12:A18),"N/A",IF(COUNTIF(M12:M18,"Not Tested")>0,"Not Tested","Counted")) | N11: =IF(M11="N/A",IF(H11="Yes",0,""),IF(M11="Not Tested",0,IF(J11="Tier",IF(M11="Fully integrated",1,IF(M11="Standalone - manual encoding",0.5,0)),IF(J11="Binary",IF(M11="Met",1,0),IF(M11="Counted",IF(N(K11)>0,IF(J11="All-or-nothing",IF(N(L11)>=K11,1,0),MIN(N(L11)/K11,1)),0),0))))) | O11: =IF(COUNTIF(M12:M18,"Not Met")>0,COUNTIF(M12:M18,"Not Met")&" of "&K11&" need compliance: "&_xlfn.TEXTJOIN("; ",TRUE(),U12:U18),IF(COUNTIF(M12:M18,"Not Tested")>0,COUNTIF(M12:M18,"Not Tested")&" of "&COUNTA(A12:A18)&" not yet tested",IF(M11="N/A","","All compliant"))) | Q11: =IF(N11="",0,I11) | R11: =IF(N11="",0,I11*N11) | S11: =IF(OR(AND(H11="Yes",M11<>"Not Tested",N11<>"",N11<1),COUNTIFS(H12:H18,"Yes",M12:M18,"Not Met")+COUNTIFS(H12:H18,"Yes",M12:M18,"N/A")>0),1,0) | T11: Criterion | V11: =COUNTA(A12:A18)-COUNTIF(M12:M18,"Not Tested") | W11: =IF(AND(T11="Criterion",I11>0,M11<>"Not Tested",N11<>"",OR(N(N11)<1,S11=1)),A11,"")
A12: L1-02.1 | B12: ↳ sub-item | C12: System overview & user roles | D12: (part of L1-02) | M12: Not Tested | O12: =IF(M12="Not Met","Needs compliance",IF(M12="Not Tested","Not yet tested","")) | T12: Sub | U12: =IF(M12="Not Met","("&1&") "&IF(H12="Yes","★ ","")&C12,"")
A13: L1-02.2 | B13: ↳ sub-item | C13: Referring workflow step-by-step | D13: (part of L1-02) | M13: Not Tested | O13: =IF(M13="Not Met","Needs compliance",IF(M13="Not Tested","Not yet tested","")) | T13: Sub | U13: =IF(M13="Not Met","("&2&") "&IF(H13="Yes","★ ","")&C13,"")
A14: L1-02.3 | B14: ↳ sub-item | C14: Receiving workflow step-by-step | D14: (part of L1-02) | M14: Not Tested | O14: =IF(M14="Not Met","Needs compliance",IF(M14="Not Tested","Not yet tested","")) | T14: Sub | U14: =IF(M14="Not Met","("&3&") "&IF(H14="Yes","★ ","")&C14,"")
A15: L1-02.4 | B15: ↳ sub-item | C15: Back-referral workflow | D15: (part of L1-02) | M15: Not Tested | O15: =IF(M15="Not Met","Needs compliance",IF(M15="Not Tested","Not yet tested","")) | T15: Sub | U15: =IF(M15="Not Met","("&4&") "&IF(H15="Yes","★ ","")&C15,"")
A16: L1-02.5 | B16: ↳ sub-item | C16: Server status check & downtime / offline behaviour | D16: (part of L1-02) | M16: Not Tested | O16: =IF(M16="Not Met","Needs compliance",IF(M16="Not Tested","Not yet tested","")) | T16: Sub | U16: =IF(M16="Not Met","("&5&") "&IF(H16="Yes","★ ","")&C16,"")
A17: L1-02.6 | B17: ↳ sub-item | C17: Troubleshooting & error messages | D17: (part of L1-02) | M17: Not Tested | O17: =IF(M17="Not Met","Needs compliance",IF(M17="Not Tested","Not yet tested","")) | T17: Sub | U17: =IF(M17="Not Met","("&6&") "&IF(H17="Yes","★ ","")&C17,"")
A18: L1-02.7 | B18: ↳ sub-item | C18: Vendor support contacts & escalation | D18: (part of L1-02) | M18: Not Tested | O18: =IF(M18="Not Met","Needs compliance",IF(M18="Not Tested","Not yet tested","")) | T18: Sub | U18: =IF(M18="Not Met","("&7&") "&IF(H18="Yes","★ ","")&C18,"")
A19: L1-03 | B19: Interfaces | C19: Supported FHIR interactions documented per resource (which resources are created, read, updated, searched), e.g. a CapabilityStatement (Connectathon Issue #3) | D19: Submit a CapabilityStatement (or equivalent) listing each FHIR resource used, its supported interactions (POST, PUT, GET, search) and search parameters. Purpose: Removes ambiguity about what the system actually sends and receives. | E19: Check the document lists each resource used in TS1/TS2 with its interactions (POST/PUT/GET/search). | F19: CapabilityStatement or equivalent document | G19: Validator (server-side check) | H19: Yes | I19: 2 | J19: Binary | M19: Not Tested | N19: =IF(M19="N/A",IF(H19="Yes",0,""),IF(M19="Not Tested",0,IF(J19="Tier",IF(M19="Fully integrated",1,IF(M19="Standalone - manual encoding",0.5,0)),IF(J19="Binary",IF(M19="Met",1,0),IF(M19="Counted",IF(N(K19)>0,IF(J19="All-or-nothing",IF(N(L19)>=K19,1,0),MIN(N(L19)/K19,1)),0),0))))) | O19: =IF(M19="Not Met","Needs compliance",IF(M19="Not Tested","Not yet tested","")) | Q19: =IF(N19="",0,I19) | R19: =IF(N19="",0,I19*N19) | S19: =IF(AND(H19="Yes",M19<>"Not Tested",N19<>"",N19<1),1,0) | T19: Criterion | W19: =IF(AND(T19="Criterion",I19>0,M19<>"Not Tested",N19<>"",OR(N(N19)<1,S19=1)),A19,"")
A20: L1-04 | B20: Architecture | C20: System architecture — integration of the eReferral function with the EMR, judged by how patient details reach the referral (not by how the system is built): (a) Fully integrated = 100% — the eReferral function is part of the EMR, OR it is a standalone system integrated with the EMR whose only role is to perform the referral and which receives the patient details automatically; (b) Standalone - manual encoding = 50% — the standalone system still requires manual intervention to encode patient details (re-typing, copy-paste or re-upload). | D20: Submit a system architecture diagram showing the EMR, the eReferral function (built-in or a separate system) and how patient details flow from the EMR record into the referral. A high-level diagram is sufficient — internal component, network or infrastructure details are not required. Any integration method is acceptable (shared database, API, FHIR, HL7 v2, other interface). Evidence options (vendor's choice — any ONE that proves compliance): (a) the full document / configuration; (b) a high-level or redacted version plus a signed attestation by an authorized officer that the control meets the referenced TB items; (c) independent certification or report (e.g., ISO/IEC 27001, SOC 2, cloud-provider compliance report, penetration-test summary letter); or (d) a view-only presentation (screen share or on site) recorded by the Validators as "sighted" with date, without keeping a copy. Source code, keys, credentials and internal network details are never required. Evidence is used only for this validation, under the Regional Validation Team's confidentiality undertaking (Instructions 4B). Purpose: What matters is that patient details recorded once in the EMR are reused without manual re-encoding. Whether the eReferral function is built into the EMR or is a separate system is the vendor's design choice and is not penalised. | E20: 1. Review the architecture diagram. 2. Demonstration: register the Test Data patient in the EMR, then start a referral. 3. Fully integrated: every patient detail already in the EMR (name, birth date, sex, PhilSys number, PhilHealth ID, address, contact number) appears in the referral without the user re-typing, copy-pasting or re-uploading it — whether the eReferral function is built into the EMR or is a separate system connected to it. 4. Standalone - manual encoding: any of these details must be encoded manually. 5. Not Met: no diagram or no demonstration. | F20: System architecture diagram (high-level is sufficient) + demonstration | G20: Validator + server-side check + Observer | H20: No | I20: 2 | J20: Tier | M20: Not Tested | N20: =IF(M20="N/A",IF(H20="Yes",0,""),IF(M20="Not Tested",0,IF(J20="Tier",IF(M20="Fully integrated",1,IF(M20="Standalone - manual encoding",0.5,0)),IF(J20="Binary",IF(M20="Met",1,0),IF(M20="Counted",IF(N(K20)>0,IF(J20="All-or-nothing",IF(N(L20)>=K20,1,0),MIN(N(L20)/K20,1)),0),0))))) | O20: =IF(M20="Not Met","Needs compliance",IF(M20="Not Tested","Not yet tested",IF(N20<1,"Integration level: "&M20,""))) | Q20: =IF(N20="",0,I20) | R20: =IF(N20="",0,I20*N20) | S20: =IF(AND(H20="Yes",M20<>"Not Tested",N20<>"",N20<1),1,0) | T20: Criterion | W20: =IF(AND(T20="Criterion",I20>0,M20<>"Not Tested",N20<>"",OR(N(N20)<1,S20=1)),A20,"")
A21: L1-05 | B21: Security design | C21: Product security and privacy design documented and stated against the Technical Baseline and NPC Circular 2023-06: (1) authentication & role-based access, (2) audit logging, (3) encryption in transit and at rest, (4) backup & recovery of data held only in the system (user accounts / credentials, audit trail, configuration), (5) privacy-by-design / privacy-by-default features — data minimisation, retention and secure disposal | D21: Submit security and privacy design documentation covering the five topics. For each topic, state the mechanism used and confirm it meets or exceeds the Technical Baseline (Reference Guide, Ch. 3) (TB-01 to TB-11). Any product, platform or method is acceptable if it meets the baseline. If an equivalent control is used instead, attach a short justification with evidence (Instructions 4A). Evidence options (vendor's choice — any ONE that proves compliance): (a) the full document / configuration; (b) a high-level or redacted version plus a signed attestation by an authorized officer that the control meets the referenced TB items; (c) independent certification or report (e.g., ISO/IEC 27001, SOC 2, cloud-provider compliance report, penetration-test summary letter); or (d) a view-only presentation (screen share or on site) recorded by the Validators as "sighted" with date, without keeping a copy. Source code, keys, credentials and internal network details are never required. Evidence is used only for this validation, under the Regional Validation Team's confidentiality undertaking (Instructions 4B). Purpose: Describes the security features the system provides, in measurable terms. Referral data exchanged is kept on the Shared Health Record; the backup covers data that exists only in the system. Topic 5 also gives facilities (the personal information controllers) what they need for their own Privacy Impact Assessment under NPC Circular 2023-06 §5 and §7. | E21: Count the five topics. A topic is Met if compliance is shown by ANY accepted evidence option (full or redacted document with signed attestation, independent certification, or view-only presentation recorded as sighted) AND it is mapped to the referenced TB items (or an equivalent control was accepted by the Technical Lead). Record the evidence option used in Notes. Level 2D tests that the controls work. Mark each sub-item (↳) below; Achieved is counted automatically. | F21: Security design document, OR redacted summary + signed attestation, OR independent certification, OR view-only presentation | G21: Validator + server-side check + Observer | H21: No | I21: 1 | J21: Count | K21: =COUNTA(A22:A26)-COUNTIF(M22:M26,"N/A") | L21: =COUNTIF(M22:M26,"Met") | M21: =IF(COUNTIF(M22:M26,"N/A")=COUNTA(A22:A26),"N/A",IF(COUNTIF(M22:M26,"Not Tested")>0,"Not Tested","Counted")) | N21: =IF(M21="N/A",IF(H21="Yes",0,""),IF(M21="Not Tested",0,IF(J21="Tier",IF(M21="Fully integrated",1,IF(M21="Standalone - manual encoding",0.5,0)),IF(J21="Binary",IF(M21="Met",1,0),IF(M21="Counted",IF(N(K21)>0,IF(J21="All-or-nothing",IF(N(L21)>=K21,1,0),MIN(N(L21)/K21,1)),0),0))))) | O21: =IF(COUNTIF(M22:M26,"Not Met")>0,COUNTIF(M22:M26,"Not Met")&" of "&K21&" need compliance: "&_xlfn.TEXTJOIN("; ",TRUE(),U22:U26),IF(COUNTIF(M22:M26,"Not Tested")>0,COUNTIF(M22:M26,"Not Tested")&" of "&COUNTA(A22:A26)&" not yet tested",IF(M21="N/A","","All compliant"))) | Q21: =IF(N21="",0,I21) | R21: =IF(N21="",0,I21*N21) | S21: =IF(OR(AND(H21="Yes",M21<>"Not Tested",N21<>"",N21<1),COUNTIFS(H22:H26,"Yes",M22:M26,"Not Met")+COUNTIFS(H22:H26,"Yes",M22:M26,"N/A")>0),1,0) | T21: Criterion | V21: =COUNTA(A22:A26)-COUNTIF(M22:M26,"Not Tested") | W21: =IF(AND(T21="Criterion",I21>0,M21<>"Not Tested",N21<>"",OR(N(N21)<1,S21=1)),A21,"")
A22: L1-05.1 | B22: ↳ sub-item | C22: Authentication & role-based access (TB-05, TB-06, TB-07) | D22: (part of L1-05) | M22: Not Tested | O22: =IF(M22="Not Met","Needs compliance",IF(M22="Not Tested","Not yet tested","")) | T22: Sub | U22: =IF(M22="Not Met","("&1&") "&IF(H22="Yes","★ ","")&C22,"")
A23: L1-05.2 | B23: ↳ sub-item | C23: Audit logging (TB-08) | D23: (part of L1-05) | M23: Not Tested | O23: =IF(M23="Not Met","Needs compliance",IF(M23="Not Tested","Not yet tested","")) | T23: Sub | U23: =IF(M23="Not Met","("&2&") "&IF(H23="Yes","★ ","")&C23,"")
A24: L1-05.3 | B24: ↳ sub-item | C24: Encryption in transit and at rest, password storage (TB-01 to TB-04) | D24: (part of L1-05) | M24: Not Tested | O24: =IF(M24="Not Met","Needs compliance",IF(M24="Not Tested","Not yet tested","")) | T24: Sub | U24: =IF(M24="Not Met","("&3&") "&IF(H24="Yes","★ ","")&C24,"")
A25: L1-05.4 | B25: ↳ sub-item | C25: Backup & recovery of data held only in the system — user accounts / credentials, audit trail, configuration (TB-09) | D25: (part of L1-05) | M25: Not Tested | O25: =IF(M25="Not Met","Needs compliance",IF(M25="Not Tested","Not yet tested","")) | T25: Sub | U25: =IF(M25="Not Met","("&4&") "&IF(H25="Yes","★ ","")&C25,"")
A26: L1-05.5 | B26: ↳ sub-item | C26: Privacy-by-design / privacy-by-default — data minimisation, retention and secure disposal (TB-11; NPC Circular 2023-06 §7–9, §28–30) | D26: (part of L1-05) | M26: Not Tested | O26: =IF(M26="Not Met","Needs compliance",IF(M26="Not Tested","Not yet tested","")) | T26: Sub | U26: =IF(M26="Not Met","("&5&") "&IF(H26="Yes","★ ","")&C26,"")
A27: L1-06 | B27: Release management | C27: Version/change management: release notes for the version under test and a committed timeline for updating to new IG versions | D27: Submit release notes for the version under test and a written timeline for adopting new PH Core / PHeReF IG versions. Purpose: Updates to the draft IGs will be applied in a controlled, traceable way. | E27: Check release notes for the version under test and the written update timeline. | F27: Release notes + update commitment | G27: Validator (server-side check) | H27: No | I27: 1 | J27: Binary | M27: Not Tested | N27: =IF(M27="N/A",IF(H27="Yes",0,""),IF(M27="Not Tested",0,IF(J27="Tier",IF(M27="Fully integrated",1,IF(M27="Standalone - manual encoding",0.5,0)),IF(J27="Binary",IF(M27="Met",1,0),IF(M27="Counted",IF(N(K27)>0,IF(J27="All-or-nothing",IF(N(L27)>=K27,1,0),MIN(N(L27)/K27,1)),0),0))))) | O27: =IF(M27="Not Met","Needs compliance",IF(M27="Not Tested","Not yet tested","")) | Q27: =IF(N27="",0,I27) | R27: =IF(N27="",0,I27*N27) | S27: =IF(AND(H27="Yes",M27<>"Not Tested",N27<>"",N27<1),1,0) | T27: Criterion | W27: =IF(AND(T27="Criterion",I27>0,M27<>"Not Tested",N27<>"",OR(N(N27)<1,S27=1)),A27,"")

Sheet L2-A TS0-Terminology
A1: Level 2A — TS0 Terminology & Registry Validation (GATE)
A2: Before submitting (TS1) or reading (TS2) an eReferral, every coded element must use the official terminology and every registry value or patient identifier must follow the official registry — the exact server, registry or API for each concept is named in the Terminology & Registry Sources (Reference Guide, Ch. 4) (SRC-01 to SRC-15). CRITICAL (must be 100%): the IG-required bindings (TS0-01, TS0-02), invalid-code handling (TS0-03), PSGC and NHFR (★ in TS0-06) and the PhilHealth / PhilSys identifiers (TS0-07) — TS1, TS2 and Level 3 cannot work without them. Other items (display text, code-system validity, NHWR, DSWD) carry normal weight but are not critical. How values are obtained (live look-up, scheduled sync or cached copy) is the vendor's choice. Test this part FIRST.
C4: Level / section score | D4: =IF(SUM(Q10:Q300)=0,0,SUM(R10:R300)/SUM(Q10:Q300)) | E4: Items not yet tested | F4: =COUNTIFS(M10:M300,"Not Tested",T10:T300,"Criterion") | G4: Count criteria: mark each sub-item (rows marked ↳). Required, Achieved, Result and Outstanding are calculated automatically.
C5: Pass threshold (set on Summary) | D5: =Summary!D10 | E5: Items marked N/A | F5: =COUNTIFS(M10:M300,"N/A",T10:T300,"Criterion")
C6: Critical criteria not met (tested items) | D6: =SUM(S10:S300) | E6: Sheet status | F6: =IF(F4>0,"INCOMPLETE",IF(AND(D6=0,D4>=D5),"PASSED","NOT PASSED"))
C7: Evaluation progress (items evaluated) | D7: =IF(F7=0,0,(F7-F4)/F7) | E7: Total items | F7: =COUNTIF(T10:T300,"Criterion")
A9: Ref ID | B9: Section | C9: Criterion (what is checked) | D9: Developer's Guide (what the vendor must prepare / implement) | E9: Validator's Guide (how the Validators verify) | F9: Evidence required | G9: Validation role | H9: Critical? | I9: Weight | J9: Scoring type | K9: Required (n) | L9: Achieved (n) | M9: Result | N9: Score % | O9: Outstanding (auto) | P9: Evidence ref. / Notes | Q9: Applicable wt | R9: Earned wt | S9: Critical fail | T9: Row type | U9: Sub not met | V9: Sub tested | W9: Needs compliance (ID)
A10: TS0-01 | B10: PH Core | C10: PH Core coded elements: values match the official PH Core / base FHIR value sets (required bindings — not locally invented) | D10: Use the PH Core / base FHIR value sets for each coded field listed (sex, contact point) — source SRC-05. Use the source named in the Terminology & Registry Sources (Reference Guide, Ch. 4) — for coded values, the DOH HIE terminology server (runtime look-up, scheduled sync or cached copy: vendor's choice). Purpose: These bindings are REQUIRED in the IG; a wrong code makes the whole referral fail validation (TS1-T.02), so this is critical. | E10: 1. Check that the system's configured terminology endpoint is the DOH HIE terminology server (Terminology & Registry Sources — Reference Guide, Ch. 4). 2. Open each field / dropdown listed as a sub-item and compare the options with the value set on the server ($expand), or check the submitted code ($validate-code). 3. A sub-item is Met only if every option / submitted code belongs to the bound value set. Mark each sub-item (↳) below; Achieved is counted automatically. ★ = critical sub-item: if it is Not Met (or N/A) the criterion counts as a critical failure. | F10: Screenshot of each dropdown + server response ($expand / $validate-code) | G10: Validator + server-side check + Observer | H10: Yes | I10: 2 | J10: Count | K10: =COUNTA(A11:A14)-COUNTIF(M11:M14,"N/A") | L10: =COUNTIF(M11:M14,"Met") | M10: =IF(COUNTIF(M11:M14,"N/A")=COUNTA(A11:A14),"N/A",IF(COUNTIF(M11:M14,"Not Tested")>0,"Not Tested","Counted")) | N10: =IF(M10="N/A",IF(H10="Yes",0,""),IF(M10="Not Tested",0,IF(J10="Tier",IF(M10="Fully integrated",1,IF(M10="Standalone - manual encoding",0.5,0)),IF(J10="Binary",IF(M10="Met",1,0),IF(M10="Counted",IF(N(K10)>0,IF(J10="All-or-nothing",IF(N(L10)>=K10,1,0),MIN(N(L10)/K10,1)),0),0))))) | O10: =IF(COUNTIF(M11:M14,"Not Met")>0,COUNTIF(M11:M14,"Not Met")&" of "&K10&" need compliance: "&_xlfn.TEXTJOIN("; ",TRUE(),U11:U14),IF(COUNTIF(M11:M14,"Not Tested")>0,COUNTIF(M11:M14,"Not Tested")&" of "&COUNTA(A11:A14)&" not yet tested",IF(M10="N/A","","All compliant"))) | Q10: =IF(N10="",0,I10) | R10: =IF(N10="",0,I10*N10) | S10: =IF(OR(AND(H10="Yes",M10<>"Not Tested",N10<>"",N10<1),COUNTIFS(H11:H14,"Yes",M11:M14,"Not Met")+COUNTIFS(H11:H14,"Yes",M11:M14,"N/A")>0),1,0) | T10: Criterion | V10: =COUNTA(A11:A14)-COUNTIF(M11:M14,"Not Tested") | W10: =IF(AND(T10="Criterion",I10>0,M10<>"Not Tested",N10<>"",OR(N(N10)<1,S10=1)),A10,"")
A11: TS0-01.1 | B11: ↳ sub-item | C11: Sex — AdministrativeGender (required binding) | D11: (part of TS0-01) | H11: Yes | M11: Not Tested | O11: =IF(M11="Not Met","Needs compliance",IF(M11="Not Tested","Not yet tested","")) | T11: Sub | U11: =IF(M11="Not Met","("&1&") "&IF(H11="Yes","★ ","")&C11,"")
A12: TS0-01.2 | B12: ↳ sub-item | C12: Contact number — ContactPointSystem / ContactPointUse (required binding) | D12: (part of TS0-01) | H12: Yes | M12: Not Tested | O12: =IF(M12="Not Met","Needs compliance",IF(M12="Not Tested","Not yet tested","")) | T12: Sub | U12: =IF(M12="Not Met","("&2&") "&IF(H12="Yes","★ ","")&C12,"")
A13: TS0-01.3 | B13: ↳ sub-item | C13: Civil status — MaritalStatus value set (required binding in ERefPatient) | D13: (part of TS0-01) | H13: Yes | M13: Not Tested | O13: =IF(M13="Not Met","Needs compliance",IF(M13="Not Tested","Not yet tested","")) | T13: Sub | U13: =IF(M13="Not Met","("&3&") "&IF(H13="Yes","★ ","")&C13,"")
A14: TS0-01.4 | B14: ↳ sub-item | C14: Accompanied by / next of kin relationship — RelatedPerson relationship type (required binding on Patient.contact.relationship) | D14: (part of TS0-01) | H14: Yes | M14: Not Tested | O14: =IF(M14="Not Met","Needs compliance",IF(M14="Not Tested","Not yet tested","")) | T14: Sub | U14: =IF(M14="Not Met","("&4&") "&IF(H14="Yes","★ ","")&C14,"")
A15: TS0-02 | B15: PHeReF | C15: PHeReF coded elements: values match the official PHeReF value sets (not locally invented) | D15: Use the PHeReF value sets for each coded field — sources SRC-01 to SRC-04 and SRC-09. Use the source named in the Terminology & Registry Sources (Reference Guide, Ch. 4) — for coded values, the DOH HIE terminology server (runtime look-up, scheduled sync or cached copy: vendor's choice). Referral Category → ServiceRequest.category (Referral Category VS, SNOMED CT: 73770003 Emergency / 440655000 Outpatient — required). Priority → ServiceRequest.priority (EReferralPriority: routine / urgent / stat — required). Reason for Referral → ServiceRequest.reasonCode (Reason for Referral (Service Type) VS, SNOMED CT). Practitioner Role → PractitionerRole.code (Practitioner Role VS — required). Task status → Task.status (FHIR TaskStatus: requested, received, accepted, rejected, completed). Purpose: TS1, TS2 and the Level 3 reports cannot work if these codes are wrong — all five are critical. | E15: 1. Check that the system's configured terminology endpoint is the DOH HIE terminology server (Terminology & Registry Sources — Reference Guide, Ch. 4). 2. Open each field / dropdown listed as a sub-item and compare the options with the value set on the server ($expand), or check the submitted code ($validate-code). 3. A sub-item is Met only if every option / submitted code belongs to the bound value set. Mark each sub-item (↳) below; Achieved is counted automatically. ★ = critical sub-item: if it is Not Met (or N/A) the criterion counts as a critical failure. | F15: Screenshot of each dropdown + server response ($expand / $validate-code) | G15: Validator + server-side check + Observer | H15: Yes | I15: 2 | J15: Count | K15: =COUNTA(A16:A20)-COUNTIF(M16:M20,"N/A") | L15: =COUNTIF(M16:M20,"Met") | M15: =IF(COUNTIF(M16:M20,"N/A")=COUNTA(A16:A20),"N/A",IF(COUNTIF(M16:M20,"Not Tested")>0,"Not Tested","Counted")) | N15: =IF(M15="N/A",IF(H15="Yes",0,""),IF(M15="Not Tested",0,IF(J15="Tier",IF(M15="Fully integrated",1,IF(M15="Standalone - manual encoding",0.5,0)),IF(J15="Binary",IF(M15="Met",1,0),IF(M15="Counted",IF(N(K15)>0,IF(J15="All-or-nothing",IF(N(L15)>=K15,1,0),MIN(N(L15)/K15,1)),0),0))))) | O15: =IF(COUNTIF(M16:M20,"Not Met")>0,COUNTIF(M16:M20,"Not Met")&" of "&K15&" need compliance: "&_xlfn.TEXTJOIN("; ",TRUE(),U16:U20),IF(COUNTIF(M16:M20,"Not Tested")>0,COUNTIF(M16:M20,"Not Tested")&" of "&COUNTA(A16:A20)&" not yet tested",IF(M15="N/A","","All compliant"))) | Q15: =IF(N15="",0,I15) | R15: =IF(N15="",0,I15*N15) | S15: =IF(OR(AND(H15="Yes",M15<>"Not Tested",N15<>"",N15<1),COUNTIFS(H16:H20,"Yes",M16:M20,"Not Met")+COUNTIFS(H16:H20,"Yes",M16:M20,"N/A")>0),1,0) | T15: Criterion | V15: =COUNTA(A16:A20)-COUNTIF(M16:M20,"Not Tested") | W15: =IF(AND(T15="Criterion",I15>0,M15<>"Not Tested",N15<>"",OR(N(N15)<1,S15=1)),A15,"")
